<robot name="shadow_rover">

  <link name="base_footprint"/>

  <joint name="base_joint" type="fixed">
    <parent link="base_footprint"/>
    <child link="base_link"/>
    <origin xyz="0 0 0" rpy="0 0 0"/>
  </joint>

  <link name="base_link">
    <inertial>
      <origin xyz="0.0284668334099027 -8.37026794222648E-05 1.132132034957292" rpy="0 0 0" />
      <mass value="150" />
      <inertia ixx="12.5939967394402" ixy="-0.000554987582194055" ixz="-0.0472151681792295"
               iyy="21.9091082607589" iyz="-0.00185025853945151" izz="31.6319646153617" />
    </inertial>
    <visual>
      <origin xyz="0 0 0" rpy="0 0 0" />
      <geometry>
        <mesh filename="file:///root/rover_ws/src/shadow_rover/meshes/base_link.STL" />
      </geometry>
      <material name="grey_blue">
        <color rgba="0.792 0.819 0.933 1" />
      </material>
    </visual>
    <collision>
      <origin xyz="0 0 0" rpy="0 0 0" />
      <geometry>
        <mesh filename="file:///root/rover_ws/src/shadow_rover/meshes/base_link.STL" />
      </geometry>
    </collision>
  </link>

  <link name="Link_FR">
    <inertial>
      <origin xyz="-1.6679E-07 -0.015081 -1.1118E-06" rpy="0 0 0" />
      <mass value="8" />
      <inertia ixx="0.084417" ixy="-3.1716E-09" ixz="8.8229E-09" iyy="0.15702" iyz="8.3722E-09" izz="0.084417" />
    </inertial>
    <visual>
      <origin xyz="0 0 0" rpy="0 0 0" />
      <geometry>
        <mesh filename="file:///root/rover_ws/src/shadow_rover/meshes/Link_FR.STL" />
      </geometry>
      <material name="grey_blue"/>
    </visual>
    <collision>
      <origin xyz="0 0 0" rpy="0 0 0" />
      <geometry>
        <mesh filename="file:///root/rover_ws/src/shadow_rover/meshes/Link_FR.STL" />
      </geometry>
    </collision>
  </link>

  <joint name="Joint_FR" type="continuous">
    <origin xyz="0.33067 0.43233 -0.36983" rpy="0 0 0" />
    <parent link="base_link" />
    <child link="Link_FR" />
    <axis xyz="0 1 0" />
  </joint>

  <link name="Link_FL">
    <inertial>
      <origin xyz="1.0931E-06 0.015081 2.6683E-07" rpy="0 0 0" />
      <mass value="8.0658" />
      <inertia ixx="0.084417" ixy="1.0107E-08" ixz="1.5954E-08" iyy="0.15702" iyz="-1.2282E-09" izz="0.084417" />
    </inertial>
    <visual>
      <origin xyz="0 0 0" rpy="0 0 0" />
      <geometry>
        <mesh filename="file:///root/rover_ws/src/shadow_rover/meshes/Link_FL.STL" />
      </geometry>
      <material name="grey_blue"/>
    </visual>
    <collision>
      <origin xyz="0 0 0" rpy="0 0 0" />
      <geometry>
        <mesh filename="file:///root/rover_ws/src/shadow_rover/meshes/Link_FL.STL" />
      </geometry>
    </collision>
  </link>

  <joint name="Joint_FL" type="continuous">
    <origin xyz="0.33067 -0.43233 -0.36983" rpy="0 0 0" />
    <parent link="base_link" />
    <child link="Link_FL" />
    <axis xyz="0 1 0" />
  </joint>

  <link name="Link_BR">
    <inertial>
      <origin xyz="1.0104E-06 -0.015081 4.9239E-07" rpy="0 0 0" />
      <mass value="8.0658" />
      <inertia ixx="0.084417" ixy="-5.1578E-09" ixz="2.8528E-08" iyy="0.15702" iyz="-8.3839E-09" izz="0.084417" />
    </inertial>
    <visual>
      <origin xyz="0 0 0" rpy="0 0 0" />
      <geometry>
        <mesh filename="file:///root/rover_ws/src/shadow_rover/meshes/Link_BR.STL" />
      </geometry>
      <material name="grey_blue"/>
    </visual>
    <collision>
      <origin xyz="0 0 0" rpy="0 0 0" />
      <geometry>
        <mesh filename="file:///root/rover_ws/src/shadow_rover/meshes/Link_BR.STL" />
      </geometry>
    </collision>
  </link>

  <joint name="Joint_BR" type="continuous">
    <origin xyz="-0.33067 0.43233 -0.36983" rpy="0 0 0" />
    <parent link="base_link" />
    <child link="Link_BR" />
    <axis xyz="0 1 0" />
  </joint>

  <link name="Link_BL">
    <inertial>
      <origin xyz="7.4427E-07 0.015081 8.4315E-07" rpy="0 0 0" />
      <mass value="8.0658" />
      <inertia ixx="0.084417" ixy="9.088E-09" ixz="3.3799E-08" iyy="0.15702" iyz="4.5321E-09" izz="0.084417" />
    </inertial>
    <visual>
      <origin xyz="0 0 0" rpy="0 0 0" />
      <geometry>
        <mesh filename="file:///root/rover_ws/src/shadow_rover/meshes/Link_BL.STL" />
      </geometry>
      <material name="grey_blue"/>
    </visual>
    <collision>
      <origin xyz="0 0 0" rpy="0 0 0" />
      <geometry>
        <mesh filename="file:///root/rover_ws/src/shadow_rover/meshes/Link_BL.STL" />
      </geometry>
    </collision>
  </link>

  <joint name="Joint_BL" type="continuous">
    <origin xyz="-0.33067 -0.43233 -0.36983" rpy="0 0 0" />
    <parent link="base_link" />
    <child link="Link_BL" />
    <axis xyz="0 1 0" />
  </joint>

  <link name="imu_link">
    <visual>
      <origin xyz="0 0 0.1" rpy="0 0 0"/>
      <geometry><box size="0.05 0.05 0.02"/></geometry>
      <material name="black"><color rgba="0 0 0 1"/></material>
    </visual>
    <collision>
      <origin xyz="0 0 0.1" rpy="0 0 0"/>
      <geometry><box size="0.05 0.05 0.02"/></geometry>
    </collision>
    <inertial>
      <mass value="0.1"/>
      <inertia ixx="0.0001" iyy="0.0001" izz="0.0001" ixy="0" ixz="0" iyz="0"/>
    </inertial>
  </link>

  <joint name="imu_joint" type="fixed">
    <parent link="base_link"/>
    <child link="imu_link"/>
    <origin xyz="0 0 -0.1" rpy="0 0 0"/>
  </joint>

  <link name="lidar_link">
    <visual>
      <origin xyz="0 0 0.15" rpy="0 0 0"/>
      <geometry><cylinder radius="0.03" length="0.05"/></geometry>
      <material name="grey"><color rgba="0.5 0.5 0.5 1"/></material>
    </visual>
  </link>

  <joint name="lidar_joint" type="fixed">
    <parent link="base_link"/>
    <child link="lidar_link"/>
    <origin xyz="0 0 0.15" rpy="0 0 0"/>
  </joint>

  <gazebo>
    <plugin name="diff_drive" filename="libgazebo_ros_diff_drive.so">
      <update_rate>50</update_rate>
      <left_joint>Joint_FL</left_joint>  <right_joint>Joint_FR</right_joint> <wheel_separation>0.86</wheel_separation> <wheel_diameter>0.4</wheel_diameter>   <max_wheel_torque>200</max_wheel_torque>
      <max_wheel_acceleration>5.0</max_wheel_acceleration>

      <command_topic>cmd_vel</command_topic>
      <publish_odom>true</publish_odom>
      <publish_odom_tf>true</publish_odom_tf>
      <odometry_frame>odom</odometry_frame>
      <robot_base_frame>base_footprint</robot_base_frame>
    </plugin>
  </gazebo>

  <gazebo reference="lidar_link">
    <sensor name="lidar" type="ray">
      <always_on>true</always_on>
      <visualize>true</visualize>
      <update_rate>10</update_rate>
      <ray>
        <scan>
          <horizontal>
            <samples>360</samples>
            <resolution>1.000000</resolution>
            <min_angle>0.000000</min_angle>
            <max_angle>6.280000</max_angle>
          </horizontal>
        </scan>
        <range>
          <min>0.120000</min>
          <max>3.5</max>
          <resolution>0.015000</resolution>
        </range>
        <noise>
          <type>gaussian</type>
          <mean>0.0</mean>
          <stddev>0.01</stddev>
        </noise>
      </ray>
      <plugin name="scan" filename="libgazebo_ros_ray_sensor.so">
        <ros>
          <remapping>~/out:=scan</remapping>
        </ros>
        <output_type>sensor_msgs/LaserScan</output_type>
        <frame_name>lidar_link</frame_name>
      </plugin>
    </sensor>
  </gazebo>

  <gazebo reference="imu_link">
    <gravity>true</gravity>
    <sensor name="imu_sensor" type="imu">
      <always_on>true</always_on>
      <update_rate>100</update_rate>
      <visualize>true</visualize>
      <topic>__default_topic__</topic>
      <plugin filename="libgazebo_ros_imu_sensor.so" name="imu_plugin">
        <topicName>imu</topicName>
        <bodyName>imu_link</bodyName>
        <updateRateHz>10.0</updateRateHz>
        <gaussianNoise>0.0</gaussianNoise>
        <xyzOffset>0 0 0</xyzOffset>
        <rpyOffset>0 0 0</rpyOffset>
        <frameName>imu_link</frameName>
        <initialOrientationAsReference>false</initialOrientationAsReference>
      </plugin>
      <pose>0 0 0 0 0 0</pose>
    </sensor>
  </gazebo>

</robot>
